Workbook
Name Bronze: String!$J$8:$J$40
Name BWSet12: String!$L$116
Name BWSet6: String!$X$116:$X$120
Name NickelWound: String!$D$8:$D$44
Name NWSet12: String!$P$133
Name NWSet6: String!$X$133:$X$139
Name PBSet12: String!$X$109:$X$112
Name PBSet6: String!$X$100:$X$106
Name PhosBronze: String!$G$8:$G$48
Name Pitch: Pitch!$A$4:$A$52
Name Plain: String!$A$8:$A$33

Sheet Read Me

Sheet 6-String
E1: Six-String Guitar
E3: Automated Balanced-Tension Calculator
E5: String Family | K5: Target Tension | M5: 0 | N5: Tension Offset Factor
F6: PB | K6: 135 | L6: lbs. | M6: =ROUND(AVERAGE(VLOOKUP(MIN(J10:J15),Pitch!$A$58:$C$106,3,FALSE),(VLOOKUP(MAX(J10:J15),Pitch!$A$58:$C$106,3,FALSE))),0) -> 52 | N6: Center Pitch Note #
M7: =VLOOKUP(M6,Pitch!$G$58:$I$106,3,FALSE) -> E3 | N7: Center Pitch
O8: String Unit Weight (UW)
G9: Pitch | H9: String Model | I9: Scale (in) | J9: Frequency | K9: Tension | M9: Offset | N9: Target Tension | O9: Ideal UW | P9: Target UW | Q9: High Match | R9: Low Match | S9: Nearest Match
F10: String 1 | G10: E4 | H10: =VLOOKUP(S10,String!$B$53:$C$78, 2, TRUE) -> PL012 | I10: 25.5 | J10: =VLOOKUP(G10, Pitch!$A$4:$B$52, 2, FALSE) -> 329.62756 | K10: =S10*(2*I10*J10)^2/386.4 -> 23.331408 | M10: =SUM(SUM(M6-VLOOKUP(G10,Pitch!$F$58:$G$106,2,FALSE)))/SUM(VLOOKUP(VLOOKUP(MAX(J10:J15),Pitch!$A$58:$B$106,2,FALSE),Pitch!$F$58:$G$106,2,FALSE)-VLOOKUP(VLOOKUP(MIN(J10:J15),Pitch!$A$58:$B$106,2,FALSE),Pitch!$F$58:$G$106,2,FALSE))*M5 -> 0 | N10: =(K6/6)*(1+M10) -> 22.5 | O10: =N10*386.4/(2*J10*I10)^2 -> 3.0763253e-05 | P10: =IF(O10<String!$B$53,String!$B$53,IF(O10>String!$B$78,String!$B$78,O10)) -> 3.0763253e-05 | Q10: =SMALL(String!$B$53:$B$78,COUNTIF(String!$B$53:$B$78,"<"&P10)+1) -> 3.19e-05 | R10: =LARGE(String!$B$53:$B$78,COUNTIF(String!$B$53:$B$78,">"&P10)+1) -> 2.93e-05 | S10: =IF((P10-Q10)>(R10-P10),Q10,R10) -> 3.19e-05
F11: String 2 | G11: B3 | H11: =VLOOKUP(S11,String!$B$53:$C$78, 2, TRUE) -> PL016 | I11: 25.5 | J11: =VLOOKUP(G11, Pitch!$A$4:$B$52, 2, FALSE) -> 246.94165 | K11: =S11*(2*I11*J11)^2/386.4 -> 23.278317 | M11: =SUM(SUM(M6-VLOOKUP(G11,Pitch!$F$58:$G$106,2,FALSE)))/SUM(VLOOKUP(VLOOKUP(MAX(J10:J15),Pitch!$A$58:$B$106,2,FALSE),Pitch!$F$58:$G$106,2,FALSE)-VLOOKUP(VLOOKUP(MIN(J10:J15),Pitch!$A$58:$B$106,2,FALSE),Pitch!$F$58:$G$106,2,FALSE))*M5 -> 0 | N11: =(K6/6)*(1+M11) -> 22.5 | O11: =N11*386.4/(2*J11*I11)^2 -> 5.4813886e-05 | P11: =IF(O11<String!$B$53,String!$B$53,IF(O11>String!$B$78,String!$B$78,O11)) -> 5.4813886e-05 | Q11: =SMALL(String!$B$53:$B$78,COUNTIF(String!$B$53:$B$78,"<"&P11)+1) -> 5.671e-05 | R11: =LARGE(String!$B$53:$B$78,COUNTIF(String!$B$53:$B$78,">"&P11)+1) -> 5.2e-05 | S11: =IF((P11-Q11)>(R11-P11),Q11,R11) -> 5.671e-05
E12: Wound | F12: String 3 | G12: G3 | H12: =IF(E12="Plain",VLOOKUP(S12,String!$B$53:$C$78,2,TRUE),IF(F6="NW",VLOOKUP(S12,String!$E$53:$FC$89,2,TRUE),IF(F6="PB",VLOOKUP(S12,String!$H$53:$I$93,2,TRUE),IF(F6="BW",VLOOKUP(S12,String!$K$53:$L$85,2,TRUE))))) -> PB021 | I12: 25.5 | J12: =VLOOKUP(G12, Pitch!$A$4:$B$52, 2, FALSE) -> 195.99772 | K12: =S12*(2*I12*J12)^2/386.4 -> 23.127945 | M12: =SUM(SUM(M6-VLOOKUP(G12,Pitch!$F$58:$G$106,2,FALSE)))/SUM(VLOOKUP(VLOOKUP(MAX(J10:J15),Pitch!$A$58:$B$106,2,FALSE),Pitch!$F$58:$G$106,2,FALSE)-VLOOKUP(VLOOKUP(MIN(J10:J15),Pitch!$A$58:$B$106,2,FALSE),Pitch!$F$58:$G$106,2,FALSE))*M5 -> 0 | N12: =(K6/6)*(1+M12) -> 22.5 | O12: =N12*386.4/(2*J12*I12)^2 -> 8.701162e-05 | P12: =IF(E12="Plain",IF(O12<String!$B$53,String!$B$53,IF(O12>String!$B$78,String!$B$78,O12)),IF(F6="NW",IF(O12<String!$E$53,String!$E$53,IF(O12>String!$E$89,String!$E$89,O12)),IF(F6="BW",IF(O12<String!$K$53,String!$K$53,IF(O12>String!$K$85,String!$K$85,O12)),IF(O12<String!$H$53,String!$H$53,IF(O12>String!$H$93,String!$H$93,O12))))) -> 8.701162e-05 | Q12: =IF(E12="Plain",SMALL(String!$B$53:$B$78,COUNTIF(String!$B$53:$B$78,"<"&P12)+1),IF(F6="NW",SMALL(String!$E$53:$F$89,COUNTIF(String!$E$53:$E$89,"<"&P12)+1),IF(F6="BW",SMALL(String!$K$53:$K$85,COUNTIF(String!$K$53:$K$85,"<"&P12)+1),SMALL(String!$H$53:$H$93,COUNTIF(String!$H$53:$H$93,"<"&P12)+1)))) -> 8.944e-05 | R12: =IF(E12="Plain",LARGE(String!$B$53:$B$78,COUNTIF(String!$B$53:$B$78,">"&P12)+1),IF(F6="NW",LARGE(String!E$53:$E$89,COUNTIF(String!$E$53:$E$89,">"&P12)+1),IF(F6="BW",LARGE(String!$K$53:$K$85,COUNTIF(String!$K$53:$K$85,">"&P12)+1),LARGE(String!$H$53:$H$93,COUNTIF(String!$H$53:$H$93,">"&P12)+1)))) -> 8.106e-05 | S12: =IF((P12-Q12)>(R12-P12),Q12,R12) -> 8.944e-05
F13: String 4 | G13: D3 | H13: =IF(F6="NW", VLOOKUP(S13,String!$E$53:$F$89, 2, TRUE), IF(F6="PB", VLOOKUP(S13,String!$H$53:$I$93, 2, TRUE), IF(F6="BW", VLOOKUP(S13,String!$K$53:$L$85, 2, TRUE)))) -> PB028 | I13: 25.5 | J13: =VLOOKUP(G13, Pitch!$A$4:$B$52, 2, FALSE) -> 146.83238 | K13: =S13*(2*I13*J13)^2/386.4 -> 23.030498 | M13: =SUM(SUM(M6-VLOOKUP(G13,Pitch!$F$58:$G$106,2,FALSE)))/SUM(VLOOKUP(VLOOKUP(MAX(J10:J15),Pitch!$A$58:$B$106,2,FALSE),Pitch!$F$58:$G$106,2,FALSE)-VLOOKUP(VLOOKUP(MIN(J10:J15),Pitch!$A$58:$B$106,2,FALSE),Pitch!$F$58:$G$106,2,FALSE))*M5 -> 0 | N13: =(K6/6)*(1+M13) -> 22.5 | O13: =N13*386.4/(2*J13*I13)^2 -> 0.00015503708 | P13: =IF(F6="NW",IF(O13<String!$E$53,String!$E$53,IF(O13>String!$E$89,String!$E$89,O13)),IF(F6="BW",IF(O13<String!$K$53,String!$K$53,IF(O13>String!$K$85,String!$K$85,O13)),IF(O13<String!$H$53,String!$H$53,IF(O13>String!$H$93,String!$H$93,O13)))) -> 0.00015503708 | Q13: =IF(F6="NW",SMALL(String!$E$53:$E$89,COUNTIF(String!$E$53:$E$89,"<"&P13)+1),IF(F6="BW",SMALL(String!$K$53:$K$85,COUNTIF(String!$K$53:$K$85,"<"&P13)+1),SMALL(String!$H$53:$H$93,COUNTIF(String!$H$53:$H$93,"<"&P13)+1))) -> 0.0001586925 | R13: =IF(F6="NW",LARGE(String!$E$53:$E$89,COUNTIF(String!$E$53:$E$89,">"&P13)+1),IF(F6="BW",LARGE(String!$K$53:$K$85,COUNTIF(String!$K$53:$K$85,">"&P13)+1),LARGE(String!$H$53:$H$93,COUNTIF(String!$H$53:$H$93,">"&P13)+1))) -> 0.00014834 | S13: =IF((P13-Q13)>(R13-P13),Q13,R13) -> 0.0001586925
F14: String 5 | G14: A2 | H14: =IF(F6="NW", VLOOKUP(S14,String!$E$53:$F$89, 2, TRUE), IF(F6="PB", VLOOKUP(S14,String!$H$53:$I$93, 2, TRUE), IF(F6="BW", VLOOKUP(S14,String!$K$53:$L$85, 2, TRUE)))) -> PB036 | I14: 25.5 | J14: =VLOOKUP(G14, Pitch!$A$4:$B$52, 2, FALSE) -> 110 | K14: =S14*(2*I14*J14)^2/386.4 -> 21.85291 | M14: =SUM(SUM(M6-VLOOKUP(G14,Pitch!$F$58:$G$106,2,FALSE)))/SUM(VLOOKUP(VLOOKUP(MAX(J10:J15),Pitch!$A$58:$B$106,2,FALSE),Pitch!$F$58:$G$106,2,FALSE)-VLOOKUP(VLOOKUP(MIN(J10:J15),Pitch!$A$58:$B$106,2,FALSE),Pitch!$F$58:$G$106,2,FALSE))*M5 -> 0 | N14: =(K6/6)*(1+M14) -> 22.5 | O14: =N14*386.4/(2*J14*I14)^2 -> 0.00027624467 | P14: =IF(F6="NW",IF(O14<String!$E$53,String!$E$53,IF(O14>String!$E$89,String!$E$89,O14)),IF(F6="BW",IF(O14<String!$K$53,String!$K$53,IF(O14>String!$K$85,String!$K$85,O14)),IF(O14<String!$H$53,String!$H$53,IF(O14>String!$H$93,String!$H$93,O14)))) -> 0.00027624467 | Q14: =IF(F6="NW",SMALL(String!$E$53:$E$89,COUNTIF(String!$E$53:$E$89,"<"&P14)+1),IF(F6="BW",SMALL(String!$K$53:$K$85,COUNTIF(String!$K$53:$K$85,"<"&P14)+1),SMALL(String!$H$53:$H$93,COUNTIF(String!$H$53:$H$93,"<"&P14)+1))) -> 0.0002933 | R14: =IF(F6="NW",LARGE(String!$E$53:$E$89,COUNTIF(String!$E$53:$E$89,">"&P14)+1),IF(F6="BW",LARGE(String!$K$53:$K$85,COUNTIF(String!$K$53:$K$85,">"&P14)+1),LARGE(String!$H$53:$H$93,COUNTIF(String!$H$53:$H$93,">"&P14)+1))) -> 0.0002683 | S14: =IF((P14-Q14)>(R14-P14),Q14,R14) -> 0.0002683
F15: String 6 | G15: E2 | H15: =IF(F6="NW", VLOOKUP(S15,String!$E$53:$F$89, 2, TRUE), IF(F6="PB", VLOOKUP(S15,String!$H$53:$I$93, 2, TRUE), IF(F6="BW", VLOOKUP(S15,String!$K$53:$L$85, 2, TRUE)))) -> PB049 | I15: 25.5 | J15: =VLOOKUP(G15, Pitch!$A$4:$B$52, 2, FALSE) -> 82.406889 | K15: =S15*(2*I15*J15)^2/386.4 -> 22.467908 | M15: =SUM(SUM(M6-VLOOKUP(G15,Pitch!$F$58:$G$106,2,FALSE)))/SUM(VLOOKUP(VLOOKUP(MAX(J10:J15),Pitch!$A$58:$B$106,2,FALSE),Pitch!$F$58:$G$106,2,FALSE)-VLOOKUP(VLOOKUP(MIN(J10:J15),Pitch!$A$58:$B$106,2,FALSE),Pitch!$F$58:$G$106,2,FALSE))*M5 -> 0 | N15: =(K6/6)*(1+M15) -> 22.5 | O15: =N15*386.4/(2*J15*I15)^2 -> 0.00049221205 | P15: =IF(F6="NW",IF(O15<String!$E$53,String!$E$53,IF(O15>String!$E$89,String!$E$89,O15)),IF(F6="BW",IF(O15<String!$K$53,String!$K$53,IF(O15>String!$K$85,String!$K$85,O15)),IF(O15<String!$H$53,String!$H$53,IF(O15>String!$H$93,String!$H$93,O15)))) -> 0.00049221205 | Q15: =IF(F6="NW",SMALL(String!$E$53:$E$89,COUNTIF(String!$E$53:$E$89,"<"&P15)+1),IF(F6="BW",SMALL(String!$K$53:$K$85,COUNTIF(String!$K$53:$K$85,"<"&P15)+1),SMALL(String!$H$53:$H$93,COUNTIF(String!$H$53:$H$93,"<"&P15)+1))) -> 0.00050744 | R15: =IF(F6="NW",LARGE(String!$E$53:$E$89,COUNTIF(String!$E$53:$E$89,">"&P15)+1),IF(F6="BW",LARGE(String!$K$53:$K$85,COUNTIF(String!$K$53:$K$85,">"&P15)+1),LARGE(String!$H$53:$H$93,COUNTIF(String!$H$53:$H$93,">"&P15)+1))) -> 0.00049151 | S15: =IF((P15-Q15)>(R15-P15),Q15,R15) -> 0.00049151
K17: =SUM(K10:K15) -> 137.08899 | L17: Total
K18: =K17/6 -> 22.848164 | L18: Average
K19: =MAX(K10:K15)-MIN(K10:K15) -> 1.4784976 | L19: Range | N19: =MAX(N10:N15)-MIN(N10:N15) -> 0 | O19: Target Range
E23: Manual Tension Calculator | N23: Reference Calculator for Pre-Packaged Sets
E24: String Family | N24: String Family | O24: String Set
F25: PB | N25: PB | O25: EJ15 10-47 Extra Light
G26: Pitch | H26: String Model | I26: Scale (in) | J26: Frequency | K26: Tension | O26: Pitch | P26: String Model | Q26: Scale (in) | R26: Frequency | S26: Tension
F27: String 1 | G27: E4 | H27: PL012 | I27: 25.5 | J27: =VLOOKUP(G27, Pitch!$A$4:$B$52, 2, FALSE) -> 329.62756 | K27: =VLOOKUP(H27,String!$A$8:$B$33, 2, FALSE)*(2*I27*J27)^2/386.4 -> 23.331408 | N27: String 1 | O27: E4 | P27: =IF(LEFT((O25),7)="EJ23 9-",String!$B$101,IF(LEFT((O25),7)="EJ15 10",String!$D$101,IF(LEFT((O25),7)="EJ16 12",String!$F$101,IF(LEFT((O25),7)="EJ17 13",String!$H$101,IF(LEFT((O25),7)="EJ18 14",String!$J$101,IF(LEFT((O25),7)="EJ26 11",String!$L$101,IF(LEFT((O25),7)="EJ19 12",String!$N$101,IF(LEFT((O25),7)="EJ10 10",String!$B$117,IF(LEFT((O25),7)="EJ11 12",String!$D$117,IF(LEFT((O25),7)="EJ12 13",String!$F$117,IF(LEFT((O25),7)="EJ13 11",String!$H$117,IF(LEFT((O25),7)="EJ14 12",String!$J$117,IF(LEFT((O25),7)="EXL110 ",String!$B$134,IF(LEFT((O25),7)="EXL110B",String!$D$134,IF(LEFT((O25),7)="EXL115 ",String!$F$134,IF(LEFT((O25),7)="EXL115B",String!$H$134,IF(LEFT((O25),7)="EXL120 ",String!$J$134,IF(LEFT((O25),7)="EXL120B",String!$L$134,String!$N$134)))))))))))))))))) -> PL010 | Q27: 25.5 | R27: =VLOOKUP(O27, Pitch!$A$4:$B$52, 2, FALSE) -> 329.62756 | S27: =VLOOKUP(P27,String!$A$8:$B$33, 2, FALSE)*(2*Q27*R27)^2/386.4 -> 16.200335
F28: String 2 | G28: B3 | H28: PL016 | I28: 25.5 | J28: =VLOOKUP(G28, Pitch!$A$4:$B$52, 2, FALSE) -> 246.94165 | K28: =VLOOKUP(H28,String!$A$8:$B$33, 2, FALSE)*(2*I28*J28)^2/386.4 -> 23.278317 | N28: String 2 | O28: B3 | P28: =IF(LEFT((O25),7)="EJ23 9-",String!$B$102,IF(LEFT((O25),7)="EJ15 10",String!$D$102,IF(LEFT((O25),7)="EJ16 12",String!$F$102,IF(LEFT((O25),7)="EJ17 13",String!$H$102,IF(LEFT((O25),7)="EJ18 14",String!$J$102,IF(LEFT((O25),7)="EJ26 11",String!$L$102,IF(LEFT((O25),7)="EJ19 12",String!$N$102,IF(LEFT((O25),7)="EJ10 10",String!$B$118,IF(LEFT((O25),7)="EJ11 12",String!$D$118,IF(LEFT((O25),7)="EJ12 13",String!$F$118,IF(LEFT((O25),7)="EJ13 11",String!$H$118,IF(LEFT((O25),7)="EJ14 12",String!$J$118,IF(LEFT((O25),7)="EXL110 ",String!$B$135,IF(LEFT((O25),7)="EXL110B",String!$D$135,IF(LEFT((O25),7)="EXL115 ",String!$F$135,IF(LEFT((O25),7)="EXL115B",String!$H$135,IF(LEFT((O25),7)="EXL120 ",String!$J$135,IF(LEFT((O25),7)="EXL120B",String!$L$135,String!$N$135)))))))))))))))))) -> PL014 | Q28: 25.5 | R28: =VLOOKUP(O28, Pitch!$A$4:$B$52, 2, FALSE) -> 246.94165 | S28: =VLOOKUP(P28,String!$A$8:$B$33, 2, FALSE)*(2*Q28*R28)^2/386.4 -> 17.823039
E29: Wound | F29: String 3 | G29: G3 | H29: PB021 | I29: 25.5 | J29: =VLOOKUP(G29, Pitch!$A$4:$B$52, 2, FALSE) -> 195.99772 | K29: =IFERROR(IF(E29="Plain",VLOOKUP(H29,String!$A$8:$B$33,2,FALSE),IF(F25="PB",VLOOKUP(H29,String!$G$8:$H$48,2,FALSE),IF(F25="BW",VLOOKUP(H29,String!$J$8:$K$40,2,FALSE),VLOOKUP(H29,String!$D$8:$E$44,2,FALSE))))*(2*I29*J29)^2/386.4,"Select String") -> 23.127945 | N29: String 3 | O29: G3 | P29: =IF(LEFT((O25),7)="EJ23 9-",String!$B$103,IF(LEFT((O25),7)="EJ15 10",String!$D$103,IF(LEFT((O25),7)="EJ16 12",String!$F$103,IF(LEFT((O25),7)="EJ17 13",String!$H$103,IF(LEFT((O25),7)="EJ18 14",String!$J$103,IF(LEFT((O25),7)="EJ26 11",String!$L$103,IF(LEFT((O25),7)="EJ19 12",String!$N$103,IF(LEFT((O25),7)="EJ10 10",String!$B$119,IF(LEFT((O25),7)="EJ11 12",String!$D$119,IF(LEFT((O25),7)="EJ12 13",String!$F$119,IF(LEFT((O25),7)="EJ13 11",String!$H$119,IF(LEFT((O25),7)="EJ14 12",String!$J$119,IF(LEFT((O25),7)="EXL110 ",String!$B$136,IF(LEFT((O25),7)="EXL110B",String!$D$136,IF(LEFT((O25),7)="EXL115 ",String!$F$136,IF(LEFT((O25),7)="EXL115B",String!$H$136,IF(LEFT((O25),7)="EXL120 ",String!$J$136,IF(LEFT((O25),7)="EXL120B",String!$L$136,String!$N$136)))))))))))))))))) -> PB023 | Q29: 25.5 | R29: =VLOOKUP(O29, Pitch!$A$4:$B$52, 2, FALSE) -> 195.99772 | S29: =IF(LEFT(P29,2)="PL",VLOOKUP(P29,String!$A$8:$B$33,2,FALSE),IF(LEFT(P29,2)="PB",VLOOKUP(P29,String!$G$8:$H$48,2,FALSE),IF(LEFT(P29,2)="BW",VLOOKUP(P29,String!$J$8:$K$40,2,FALSE),VLOOKUP(P29,String!$D$8:$E$44,2,FALSE))))*(2*Q29*R29)^2/386.4 -> 27.92989
F30: String 4 | G30: D3 | H30: PB028 | I30: 25.5 | J30: =VLOOKUP(G30, Pitch!$A$4:$B$52, 2, FALSE) -> 146.83238 | K30: =IFERROR(IF(F25="PB",VLOOKUP(H30,String!$G$8:$H$48,2,FALSE),IF(F25="BW",VLOOKUP(H30,String!$J$8:$K$40,2,FALSE),VLOOKUP(H30,String!$D$8:$E$44,2,FALSE)))*(2*I30*J30)^2/386.4,"Select String") -> 23.030498 | N30: String 4 | O30: D3 | P30: =IF(LEFT((O25),7)="EJ23 9-",String!$B$104,IF(LEFT((O25),7)="EJ15 10",String!$D$104,IF(LEFT((O25),7)="EJ16 12",String!$F$104,IF(LEFT((O25),7)="EJ17 13",String!$H$104,IF(LEFT((O25),7)="EJ18 14",String!$J$104,IF(LEFT((O25),7)="EJ26 11",String!$L$104,IF(LEFT((O25),7)="EJ19 12",String!$N$104,IF(LEFT((O25),7)="EJ10 10",String!$B$120,IF(LEFT((O25),7)="EJ11 12",String!$D$120,IF(LEFT((O25),7)="EJ12 13",String!$F$120,IF(LEFT((O25),7)="EJ13 11",String!$H$120,IF(LEFT((O25),7)="EJ14 12",String!$J$120,IF(LEFT((O25),7)="EXL110 ",String!$B$137,IF(LEFT((O25),7)="EXL110B",String!$D$137,IF(LEFT((O25),7)="EXL115 ",String!$F$137,IF(LEFT((O25),7)="EXL115B",String!$H$137,IF(LEFT((O25),7)="EXL120 ",String!$J$137,IF(LEFT((O25),7)="EXL120B",String!$L$137,String!$N$137)))))))))))))))))) -> PB030 | Q30: 25.5 | R30: =VLOOKUP(O30, Pitch!$A$4:$B$52, 2, FALSE) -> 146.83238 | S30: =IF(LEFT(P30,2)="PL",VLOOKUP(P30,String!$A$8:$B$33,2,FALSE),IF(LEFT(P30,2)="PB",VLOOKUP(P30,String!$G$8:$H$48,2,FALSE),IF(LEFT(P30,2)="BW",VLOOKUP(P30,String!$J$8:$K$40,2,FALSE),VLOOKUP(P30,String!$D$8:$E$44,2,FALSE))))*(2*Q30*R30)^2/386.4 -> 27.080618
F31: String 5 | G31: A2 | H31: PB036 | I31: 25.5 | J31: =VLOOKUP(G31, Pitch!$A$4:$B$52, 2, FALSE) -> 110 | K31: =IFERROR(IF(F25="PB",VLOOKUP(H31,String!$G$8:$H$48,2,FALSE),IF(F25="BW",VLOOKUP(H31,String!$J$8:$K$40,2,FALSE),VLOOKUP(H31,String!$D$8:$E$44,2,FALSE)))*(2*I31*J31)^2/386.4,"Select String") -> 21.85291 | N31: String 5 | O31: A2 | P31: =IF(LEFT((O25),7)="EJ23 9-",String!$B$105,IF(LEFT((O25),7)="EJ15 10",String!$D$105,IF(LEFT((O25),7)="EJ16 12",String!$F$105,IF(LEFT((O25),7)="EJ17 13",String!$H$105,IF(LEFT((O25),7)="EJ18 14",String!$J$105,IF(LEFT((O25),7)="EJ26 11",String!$L$105,IF(LEFT((O25),7)="EJ19 12",String!$N$105,IF(LEFT((O25),7)="EJ10 10",String!$B$121,IF(LEFT((O25),7)="EJ11 12",String!$D$121,IF(LEFT((O25),7)="EJ12 13",String!$F$121,IF(LEFT((O25),7)="EJ13 11",String!$H$121,IF(LEFT((O25),7)="EJ14 12",String!$J$121,IF(LEFT((O25),7)="EXL110 ",String!$B$138,IF(LEFT((O25),7)="EXL110B",String!$D$138,IF(LEFT((O25),7)="EXL115 ",String!$F$138,IF(LEFT((O25),7)="EXL115B",String!$H$138,IF(LEFT((O25),7)="EXL120 ",String!$J$138,IF(LEFT((O25),7)="EXL120B",String!$L$138,String!$N$138)))))))))))))))))) -> PB039 | Q31: 25.5 | R31: =VLOOKUP(O31, Pitch!$A$4:$B$52, 2, FALSE) -> 110 | S31: =IF(LEFT(P31,2)="PL",VLOOKUP(P31,String!$A$8:$B$33,2,FALSE),IF(LEFT(P31,2)="PB",VLOOKUP(P31,String!$G$8:$H$48,2,FALSE),IF(LEFT(P31,2)="BW",VLOOKUP(P31,String!$J$8:$K$40,2,FALSE),VLOOKUP(P31,String!$D$8:$E$44,2,FALSE))))*(2*Q31*R31)^2/386.4 -> 25.351168
F32: String 6 | G32: E2 | H32: PB049 | I32: 25.5 | J32: =VLOOKUP(G32, Pitch!$A$4:$B$52, 2, FALSE) -> 82.406889 | K32: =IFERROR(IF(F25="PB",VLOOKUP(H32,String!$G$8:$H$48,2,FALSE),IF(F25="BW",VLOOKUP(H32,String!$J$8:$K$40,2,FALSE),VLOOKUP(H32,String!$D$8:$E$44,2,FALSE)))*(2*I32*J32)^2/386.4,"Select String") -> 22.467908 | N32: String 6 | O32: E2 | P32: =IF(LEFT((O25),7)="EJ23 9-",String!$B$106,IF(LEFT((O25),7)="EJ15 10",String!$D$106,IF(LEFT((O25),7)="EJ16 12",String!$F$106,IF(LEFT((O25),7)="EJ17 13",String!$H$106,IF(LEFT((O25),7)="EJ18 14",String!$J$106,IF(LEFT((O25),7)="EJ26 11",String!$L$106,IF(LEFT((O25),7)="EJ19 12",String!$N$106,IF(LEFT((O25),7)="EJ10 10",String!$B$122,IF(LEFT((O25),7)="EJ11 12",String!$D$122,IF(LEFT((O25),7)="EJ12 13",String!$F$122,IF(LEFT((O25),7)="EJ13 11",String!$H$122,IF(LEFT((O25),7)="EJ14 12",String!$J$122,IF(LEFT((O25),7)="EXL110 ",String!$B$139,IF(LEFT((O25),7)="EXL110B",String!$D$139,IF(LEFT((O25),7)="EXL115 ",String!$F$139,IF(LEFT((O25),7)="EXL115B",String!$H$139,IF(LEFT((O25),7)="EXL120 ",String!$J$139,IF(LEFT((O25),7)="EXL120B",String!$L$139,String!$N$139)))))))))))))))))) -> PB047 | Q32: 25.5 | R32: =VLOOKUP(O32, Pitch!$A$4:$B$52, 2, FALSE) -> 82.406889 | S32: =IF(LEFT(P32,2)="PL",VLOOKUP(P32,String!$A$8:$B$33,2,FALSE),IF(LEFT(P32,2)="PB",VLOOKUP(P32,String!$G$8:$H$48,2,FALSE),IF(LEFT(P32,2)="BW",VLOOKUP(P32,String!$J$8:$K$40,2,FALSE),VLOOKUP(P32,String!$D$8:$E$44,2,FALSE))))*(2*Q32*R32)^2/386.4 -> 20.70251
J34: Total | K34: =SUM(K27:K32) -> 137.08899 | R34: Total | S34: =SUM(S27:S32) -> 135.08756
J35: Average | K35: =K34/6 -> 22.848164 | R35: Average | S35: =S34/6 -> 22.514593
J36: Range | K36: =MAX(K27:K32)-MIN(K27:K32) -> 1.4784976 | R36: Range | S36: =MAX(S27:S32)-MIN(S27:S32) -> 11.729556

Sheet 12-String
E1: Twelve-String Guitar
E3: Automated Balanced-Tension Calculator
E5: String Family | K5: Target Tension | M5: 0 | N5: Tension Offset Factor
F6: PB | K6: 250 | L6: lbs. | M6: =ROUND(AVERAGE(VLOOKUP(MIN(J10:J21),Pitch!$A$58:$C$106,3,FALSE),(VLOOKUP(MAX(J10:J21),Pitch!$A$58:$C$106,3,FALSE))),0) -> 54 | N6: Center Pitch Note #
M7: =VLOOKUP(M6,Pitch!$G$58:$I$106,3,FALSE) -> F#3 | N7: Center Pitch
O8: String Unit Weight (UW)
G9: Pitch | H9: String Model | I9: Scale (in) | J9: Frequency | K9: Tension | L9: Tension/Course | M9: Offset | N9: Target Tension | O9: Ideal UW | P9: Target UW | Q9: High Match | R9: Low Match | S9: Nearest Match
F10: String 1 | G10: E4 | H10: =VLOOKUP(S10,String!$B$53:$C$78, 2, TRUE) -> PL0115 | I10: 25.5 | J10: =VLOOKUP(G10, Pitch!$A$4:$B$52, 2, FALSE) -> 329.62756 | K10: =S10*(2*I10*J10)^2/386.4 -> 21.429788 | M10: =SUM(SUM(M6-VLOOKUP(G10,Pitch!$F$58:$G$106,2,FALSE)))/SUM(VLOOKUP(VLOOKUP(MAX(J10:J21),Pitch!$A$58:$B$106,2,FALSE),Pitch!$F$58:$G$106,2,FALSE)-VLOOKUP(VLOOKUP(MIN(J10:J21),Pitch!$A$58:$B$106,2,FALSE),Pitch!$F$58:$G$106,2,FALSE))*M5 -> 0 | N10: =(K6/12)*(1+M10) -> 20.833333 | O10: =N10*386.4/(2*J10*I10)^2 -> 2.8484494e-05 | P10: =IF(O10<String!$B$53,String!$B$53,IF(O10>String!$B$78,String!$B$78,O10)) -> 2.8484494e-05 | Q10: =SMALL(String!$B$53:$B$78,COUNTIF(String!$B$53:$B$78,"<"&P10)+1) -> 2.93e-05 | R10: =LARGE(String!$B$53:$B$78,COUNTIF(String!$B$53:$B$78,">"&P10)+1) -> 2.68e-05 | S10: =IF((P10-Q10)>(R10-P10),Q10,R10) -> 2.93e-05
F11: String 2 | G11: E4 | H11: =VLOOKUP(S11,String!$B$53:$C$78, 2, TRUE) -> PL0115 | I11: 25.5 | J11: =VLOOKUP(G11, Pitch!$A$4:$B$52, 2, FALSE) -> 329.62756 | K11: =S11*(2*I11*J11)^2/386.4 -> 21.429788 | L11: =K10+K11 -> 42.859576 | M11: =SUM(SUM(M6-VLOOKUP(G11,Pitch!$F$58:$G$106,2,FALSE)))/SUM(VLOOKUP(VLOOKUP(MAX(J10:J21),Pitch!$A$58:$B$106,2,FALSE),Pitch!$F$58:$G$106,2,FALSE)-VLOOKUP(VLOOKUP(MIN(J10:J21),Pitch!$A$58:$B$106,2,FALSE),Pitch!$F$58:$G$106,2,FALSE))*M5 -> 0 | N11: =(K6/12)*(1+M11) -> 20.833333 | O11: =N11*386.4/(2*J11*I11)^2 -> 2.8484494e-05 | P11: =IF(O11<String!$B$53,String!$B$53,IF(O11>String!$B$78,String!$B$78,O11)) -> 2.8484494e-05 | Q11: =SMALL(String!$B$53:$B$78,COUNTIF(String!$B$53:$B$78,"<"&P11)+1) -> 2.93e-05 | R11: =LARGE(String!$B$53:$B$78,COUNTIF(String!$B$53:$B$78,">"&P11)+1) -> 2.68e-05 | S11: =IF((P11-Q11)>(R11-P11),Q11,R11) -> 2.93e-05
F12: String 3 | G12: B3 | H12: =VLOOKUP(S12,String!$B$53:$C$78, 2, TRUE) -> PL015 | I12: 25.5 | J12: =VLOOKUP(G12, Pitch!$A$4:$B$52, 2, FALSE) -> 246.94165 | K12: =S12*(2*I12*J12)^2/386.4 -> 20.45832 | M12: =SUM(SUM(M6-VLOOKUP(G12,Pitch!$F$58:$G$106,2,FALSE)))/SUM(VLOOKUP(VLOOKUP(MAX(J10:J21),Pitch!$A$58:$B$106,2,FALSE),Pitch!$F$58:$G$106,2,FALSE)-VLOOKUP(VLOOKUP(MIN(J10:J21),Pitch!$A$58:$B$106,2,FALSE),Pitch!$F$58:$G$106,2,FALSE))*M5 -> 0 | N12: =(K6/12)*(1+M12) -> 20.833333 | O12: =N12*386.4/(2*J12*I12)^2 -> 5.0753598e-05 | P12: =IF(O12<String!$B$53,String!$B$53,IF(O12>String!$B$78,String!$B$78,O12)) -> 5.0753598e-05 | Q12: =SMALL(String!$B$53:$B$78,COUNTIF(String!$B$53:$B$78,"<"&P12)+1) -> 5.2e-05 | R12: =LARGE(String!$B$53:$B$78,COUNTIF(String!$B$53:$B$78,">"&P12)+1) -> 4.984e-05 | S12: =IF((P12-Q12)>(R12-P12),Q12,R12) -> 4.984e-05
F13: String 4 | G13: B3 | H13: =VLOOKUP(S13,String!$B$53:$C$78, 2, TRUE) -> PL015 | I13: 25.5 | J13: =VLOOKUP(G13, Pitch!$A$4:$B$52, 2, FALSE) -> 246.94165 | K13: =S13*(2*I13*J13)^2/386.4 -> 20.45832 | L13: =K12+K13 -> 40.916639 | M13: =SUM(SUM(M6-VLOOKUP(G13,Pitch!$F$58:$G$106,2,FALSE)))/SUM(VLOOKUP(VLOOKUP(MAX(J10:J21),Pitch!$A$58:$B$106,2,FALSE),Pitch!$F$58:$G$106,2,FALSE)-VLOOKUP(VLOOKUP(MIN(J10:J21),Pitch!$A$58:$B$106,2,FALSE),Pitch!$F$58:$G$106,2,FALSE))*M5 -> 0 | N13: =(K6/12)*(1+M13) -> 20.833333 | O13: =N13*386.4/(2*J13*I13)^2 -> 5.0753598e-05 | P13: =IF(O13<String!$B$53,String!$B$53,IF(O13>String!$B$78,String!$B$78,O13)) -> 5.0753598e-05 | Q13: =SMALL(String!$B$53:$B$78,COUNTIF(String!$B$53:$B$78,"<"&P13)+1) -> 5.2e-05 | R13: =LARGE(String!$B$53:$B$78,COUNTIF(String!$B$53:$B$78,">"&P13)+1) -> 4.984e-05 | S13: =IF((P13-Q13)>(R13-P13),Q13,R13) -> 4.984e-05
E14: Wound | F14: String 5 | G14: G3 | H14: =IF(E14="Plain",VLOOKUP(S14,String!$B$53:$C$78,2,TRUE),IF(F6="NW",VLOOKUP(S14,String!$E$53:$FC$89,2,TRUE),IF(F6="PB",VLOOKUP(S14,String!$H$53:$I$93,2,TRUE),IF(F6="BW",VLOOKUP(S14,String!$K$53:$L$85,2,TRUE))))) -> PB020 | I14: 25.5 | J14: =VLOOKUP(G14, Pitch!$A$4:$B$52, 2, FALSE) -> 195.99772 | K14: =S14*(2*I14*J14)^2/386.4 -> 20.960994 | M14: =SUM(SUM(M6-VLOOKUP(G14,Pitch!$F$58:$G$106,2,FALSE)))/SUM(VLOOKUP(VLOOKUP(MAX(J10:J21),Pitch!$A$58:$B$106,2,FALSE),Pitch!$F$58:$G$106,2,FALSE)-VLOOKUP(VLOOKUP(MIN(J10:J21),Pitch!$A$58:$B$106,2,FALSE),Pitch!$F$58:$G$106,2,FALSE))*M5 -> 0 | N14: =(K6/12)*(1+M14) -> 20.833333 | O14: =N14*386.4/(2*J14*I14)^2 -> 8.0566315e-05 | P14: =IF(E14="Plain",IF(O14<String!$B$53,String!$B$53,IF(O14>String!$B$78,String!$B$78,O14)),IF(F6="NW",IF(O14<String!$E$53,String!$E$53,IF(O14>String!$E$89,String!$E$89,O14)),IF(F6="BW",IF(O14<String!$K$53,String!$K$53,IF(O14>String!$K$85,String!$K$85,O14)),IF(O14<String!$H$53,String!$H$53,IF(O14>String!$H$93,String!$H$93,O14))))) -> 8.0566315e-05 | Q14: =IF(E14="Plain",SMALL(String!$B$53:$B$78,COUNTIF(String!$B$53:$B$78,"<"&P14)+1),IF(F6="NW",SMALL(String!$E$53:$F$89,COUNTIF(String!$E$53:$E$89,"<"&P14)+1),IF(F6="BW",SMALL(String!$K$53:$K$85,COUNTIF(String!$K$53:$K$85,"<"&P14)+1),SMALL(String!$H$53:$H$93,COUNTIF(String!$H$53:$H$93,"<"&P14)+1)))) -> 8.106e-05 | R14: =IF(E14="Plain",LARGE(String!$B$53:$B$78,COUNTIF(String!$B$53:$B$78,">"&P14)+1),IF(F6="NW",LARGE(String!E$53:$E$89,COUNTIF(String!$E$53:$E$89,">"&P14)+1),IF(F6="BW",LARGE(String!$K$53:$K$85,COUNTIF(String!$K$53:$K$85,">"&P14)+1),LARGE(String!$H$53:$H$93,COUNTIF(String!$H$53:$H$93,">"&P14)+1)))) -> 5.96925e-05 | S14: =IF((P14-Q14)>(R14-P14),Q14,R14) -> 8.106e-05
F15: String 6 | G15: G4 | H15: =VLOOKUP(S15,String!$B$53:$C$78, 2, TRUE) -> PL0095 | I15: 25.5 | J15: =VLOOKUP(G15, Pitch!$A$4:$B$52, 2, FALSE) -> 391.99544 | K15: =S15*(2*I15*J15)^2/386.4 -> 20.676549 | L15: =K14+K15 -> 41.637542 | M15: =SUM(SUM(M6-VLOOKUP(G15,Pitch!$F$58:$G$106,2,FALSE)))/SUM(VLOOKUP(VLOOKUP(MAX(J10:J21),Pitch!$A$58:$B$106,2,FALSE),Pitch!$F$58:$G$106,2,FALSE)-VLOOKUP(VLOOKUP(MIN(J10:J21),Pitch!$A$58:$B$106,2,FALSE),Pitch!$F$58:$G$106,2,FALSE))*M5 -> 0 | N15: =(K6/12)*(1+M15) -> 20.833333 | O15: =N15*386.4/(2*J15*I15)^2 -> 2.0141579e-05 | P15: =IF(O15<String!$B$53,String!$B$53,IF(O15>String!$B$78,String!$B$78,O15)) -> 2.0141579e-05 | Q15: =SMALL(String!$B$53:$B$78,COUNTIF(String!$B$53:$B$78,"<"&P15)+1) -> 2.215e-05 | R15: =LARGE(String!$B$53:$B$78,COUNTIF(String!$B$53:$B$78,">"&P15)+1) -> 1.999e-05 | S15: =IF((P15-Q15)>(R15-P15),Q15,R15) -> 1.999e-05
F16: String 7 | G16: D3 | H16: =IF(F6="NW", VLOOKUP(S16,String!$E$53:$F$89, 2, TRUE), IF(F6="PB", VLOOKUP(S16,String!$H$53:$I$93, 2, TRUE), IF(F6="BW", VLOOKUP(S16,String!$K$53:$L$85, 2, TRUE)))) -> PB027 | I16: 25.5 | J16: =VLOOKUP(G16, Pitch!$A$4:$B$52, 2, FALSE) -> 146.83238 | K16: =S16*(2*I16*J16)^2/386.4 -> 21.528076 | M16: =SUM(SUM(M6-VLOOKUP(G16,Pitch!$F$58:$G$106,2,FALSE)))/SUM(VLOOKUP(VLOOKUP(MAX(J10:J21),Pitch!$A$58:$B$106,2,FALSE),Pitch!$F$58:$G$106,2,FALSE)-VLOOKUP(VLOOKUP(MIN(J10:J21),Pitch!$A$58:$B$106,2,FALSE),Pitch!$F$58:$G$106,2,FALSE))*M5 -> 0 | N16: =(K6/12)*(1+M16) -> 20.833333 | O16: =N16*386.4/(2*J16*I16)^2 -> 0.00014355285 | P16: =IF(F6="NW",IF(O16<String!$E$53,String!$E$53,IF(O16>String!$E$89,String!$E$89,O16)),IF(F6="BW",IF(O16<String!$K$53,String!$K$53,IF(O16>String!$K$85,String!$K$85,O16)),IF(O16<String!$H$53,String!$H$53,IF(O16>String!$H$93,String!$H$93,O16)))) -> 0.00014355285 | Q16: =IF(F6="NW",SMALL(String!$E$53:$E$89,COUNTIF(String!$E$53:$E$89,"<"&P16)+1),IF(F6="BW",SMALL(String!$K$53:$K$85,COUNTIF(String!$K$53:$K$85,"<"&P16)+1),SMALL(String!$H$53:$H$93,COUNTIF(String!$H$53:$H$93,"<"&P16)+1))) -> 0.00014834 | R16: =IF(F6="NW",LARGE(String!$E$53:$E$89,COUNTIF(String!$E$53:$E$89,">"&P16)+1),IF(F6="BW",LARGE(String!$K$53:$K$85,COUNTIF(String!$K$53:$K$85,">"&P16)+1),LARGE(String!$H$53:$H$93,COUNTIF(String!$H$53:$H$93,">"&P16)+1))) -> 0.0001364 | S16: =IF((P16-Q16)>(R16-P16),Q16,R16) -> 0.00014834
F17: String 8 | G17: D4 | H17: =VLOOKUP(S17,String!$B$53:$C$78, 2, TRUE) -> PL013 | I17: 25.5 | J17: =VLOOKUP(G17, Pitch!$A$4:$B$52, 2, FALSE) -> 293.66477 | K17: =S17*(2*I17*J17)^2/386.4 -> 21.734155 | L17: =K16+K17 -> 43.262231 | M17: =SUM(SUM(M6-VLOOKUP(G17,Pitch!$F$58:$G$106,2,FALSE)))/SUM(VLOOKUP(VLOOKUP(MAX(J10:J21),Pitch!$A$58:$B$106,2,FALSE),Pitch!$F$58:$G$106,2,FALSE)-VLOOKUP(VLOOKUP(MIN(J10:J21),Pitch!$A$58:$B$106,2,FALSE),Pitch!$F$58:$G$106,2,FALSE))*M5 -> 0 | N17: =(K6/12)*(1+M17) -> 20.833333 | O17: =N17*386.4/(2*J17*I17)^2 -> 3.5888213e-05 | P17: =IF(O17<String!$B$53,String!$B$53,IF(O17>String!$B$78,String!$B$78,O17)) -> 3.5888213e-05 | Q17: =SMALL(String!$B$53:$B$78,COUNTIF(String!$B$53:$B$78,"<"&P17)+1) -> 3.744e-05 | R17: =LARGE(String!$B$53:$B$78,COUNTIF(String!$B$53:$B$78,">"&P17)+1) -> 3.41e-05 | S17: =IF((P17-Q17)>(R17-P17),Q17,R17) -> 3.744e-05
F18: String 9 | G18: A2 | H18: =IF(F6="NW", VLOOKUP(S18,String!$E$53:$F$89, 2, TRUE), IF(F6="PB", VLOOKUP(S18,String!$H$53:$I$93, 2, TRUE), IF(F6="BW", VLOOKUP(S18,String!$K$53:$L$85, 2, TRUE)))) -> PB035 | I18: 25.5 | J18: =VLOOKUP(G18, Pitch!$A$4:$B$52, 2, FALSE) -> 110 | K18: =S18*(2*I18*J18)^2/386.4 -> 20.659674 | M18: =SUM(SUM(M6-VLOOKUP(G18,Pitch!$F$58:$G$106,2,FALSE)))/SUM(VLOOKUP(VLOOKUP(MAX(J10:J21),Pitch!$A$58:$B$106,2,FALSE),Pitch!$F$58:$G$106,2,FALSE)-VLOOKUP(VLOOKUP(MIN(J10:J21),Pitch!$A$58:$B$106,2,FALSE),Pitch!$F$58:$G$106,2,FALSE))*M5 -> 0 | N18: =(K6/12)*(1+M18) -> 20.833333 | O18: =N18*386.4/(2*J18*I18)^2 -> 0.00025578211 | P18: =IF(F6="NW",IF(O18<String!$E$53,String!$E$53,IF(O18>String!$E$89,String!$E$89,O18)),IF(F6="BW",IF(O18<String!$K$53,String!$K$53,IF(O18>String!$K$85,String!$K$85,O18)),IF(O18<String!$H$53,String!$H$53,IF(O18>String!$H$93,String!$H$93,O18)))) -> 0.00025578211 | Q18: =IF(F6="NW",SMALL(String!$E$53:$E$89,COUNTIF(String!$E$53:$E$89,"<"&P18)+1),IF(F6="BW",SMALL(String!$K$53:$K$85,COUNTIF(String!$K$53:$K$85,"<"&P18)+1),SMALL(String!$H$53:$H$93,COUNTIF(String!$H$53:$H$93,"<"&P18)+1))) -> 0.0002683 | R18: =IF(F6="NW",LARGE(String!$E$53:$E$89,COUNTIF(String!$E$53:$E$89,">"&P18)+1),IF(F6="BW",LARGE(String!$K$53:$K$85,COUNTIF(String!$K$53:$K$85,">"&P18)+1),LARGE(String!$H$53:$H$93,COUNTIF(String!$H$53:$H$93,">"&P18)+1))) -> 0.00025365 | S18: =IF((P18-Q18)>(R18-P18),Q18,R18) -> 0.00025365
E19: Plain | F19: String 10 | G19: A3 | H19: =IF(E19="Plain",VLOOKUP(S19,String!$B$53:$C$78,2,TRUE),IF(F6="NW",VLOOKUP(S19,String!$E$53:$FC$89,2,TRUE),IF(F6="PB",VLOOKUP(S19,String!$H$53:$I$93,2,TRUE),IF(F6="BW",VLOOKUP(S19,String!$K$53:$L$85,2,TRUE))))) -> PL017 | I19: 25.5 | J19: =VLOOKUP(G19, Pitch!$A$4:$B$52, 2, FALSE) -> 220 | K19: =S19*(2*I19*J19)^2/386.4 -> 20.857597 | L19: =K18+K19 -> 41.517271 | M19: =SUM(SUM(M6-VLOOKUP(G19,Pitch!$F$58:$G$106,2,FALSE)))/SUM(VLOOKUP(VLOOKUP(MAX(J10:J21),Pitch!$A$58:$B$106,2,FALSE),Pitch!$F$58:$G$106,2,FALSE)-VLOOKUP(VLOOKUP(MIN(J10:J21),Pitch!$A$58:$B$106,2,FALSE),Pitch!$F$58:$G$106,2,FALSE))*M5 -> 0 | N19: =(K6/12)*(1+M19) -> 20.833333 | O19: =N19*386.4/(2*J19*I19)^2 -> 6.3945526e-05 | P19: =IF(E19="Plain",IF(O19<String!$B$53,String!$B$53,IF(O19>String!$B$78,String!$B$78,O19)),IF(F6="NW",IF(O19<String!$E$53,String!$E$53,IF(O19>String!$E$89,String!$E$89,O19)),IF(F6="BW",IF(O19<String!$K$53,String!$K$53,IF(O19>String!$K$85,String!$K$85,O19)),IF(O19<String!$H$53,String!$H$53,IF(O19>String!$H$93,String!$H$93,O19))))) -> 6.3945526e-05 | Q19: =IF(E19="Plain",SMALL(String!$B$53:$B$78,COUNTIF(String!$B$53:$B$78,"<"&P19)+1),IF(F6="NW",SMALL(String!$E$53:$F$89,COUNTIF(String!$E$53:$E$89,"<"&P19)+1),IF(F6="BW",SMALL(String!$K$53:$K$85,COUNTIF(String!$K$53:$K$85,"<"&P19)+1),SMALL(String!$H$53:$H$93,COUNTIF(String!$H$53:$H$93,"<"&P19)+1)))) -> 6.402e-05 | R19: =IF(E19="Plain",LARGE(String!$B$53:$B$78,COUNTIF(String!$B$53:$B$78,">"&P19)+1),IF(F6="NW",LARGE(String!E$53:$E$89,COUNTIF(String!$E$53:$E$89,">"&P19)+1),IF(F6="BW",LARGE(String!$K$53:$K$85,COUNTIF(String!$K$53:$K$85,">"&P19)+1),LARGE(String!$H$53:$H$93,COUNTIF(String!$H$53:$H$93,">"&P19)+1)))) -> 5.97e-05 | S19: =IF((P19-Q19)>(R19-P19),Q19,R19) -> 6.402e-05
F20: String 11 | G20: E2 | H20: =IF(F6="NW", VLOOKUP(S20,String!$E$53:$F$89, 2, TRUE), IF(F6="PB", VLOOKUP(S20,String!$H$53:$I$93, 2, TRUE), IF(F6="BW", VLOOKUP(S20,String!$K$53:$L$85, 2, TRUE)))) -> PB047 | I20: 25.5 | J20: =VLOOKUP(G20, Pitch!$A$4:$B$52, 2, FALSE) -> 82.406889 | K20: =S20*(2*I20*J20)^2/386.4 -> 20.70251 | M20: =SUM(SUM(M6-VLOOKUP(G20,Pitch!$F$58:$G$106,2,FALSE)))/SUM(VLOOKUP(VLOOKUP(MAX(J10:J21),Pitch!$A$58:$B$106,2,FALSE),Pitch!$F$58:$G$106,2,FALSE)-VLOOKUP(VLOOKUP(MIN(J10:J21),Pitch!$A$58:$B$106,2,FALSE),Pitch!$F$58:$G$106,2,FALSE))*M5 -> 0 | N20: =(K6/12)*(1+M20) -> 20.833333 | O20: =N20*386.4/(2*J20*I20)^2 -> 0.0004557519 | P20: =IF(F6="NW",IF(O20<String!$E$53,String!$E$53,IF(O20>String!$E$89,String!$E$89,O20)),IF(F6="BW",IF(O20<String!$K$53,String!$K$53,IF(O20>String!$K$85,String!$K$85,O20)),IF(O20<String!$H$53,String!$H$53,IF(O20>String!$H$93,String!$H$93,O20)))) -> 0.0004557519 | Q20: =IF(F6="NW",SMALL(String!$E$53:$E$89,COUNTIF(String!$E$53:$E$89,"<"&P20)+1),IF(F6="BW",SMALL(String!$K$53:$K$85,COUNTIF(String!$K$53:$K$85,"<"&P20)+1),SMALL(String!$H$53:$H$93,COUNTIF(String!$H$53:$H$93,"<"&P20)+1))) -> 0.00046728 | R20: =IF(F6="NW",LARGE(String!$E$53:$E$89,COUNTIF(String!$E$53:$E$89,">"&P20)+1),IF(F6="BW",LARGE(String!$K$53:$K$85,COUNTIF(String!$K$53:$K$85,">"&P20)+1),LARGE(String!$H$53:$H$93,COUNTIF(String!$H$53:$H$93,">"&P20)+1))) -> 0.00045289 | S20: =IF((P20-Q20)>(R20-P20),Q20,R20) -> 0.00045289
F21: String 12 | G21: E3 | H21: =IF(F6="NW", VLOOKUP(S21,String!$E$53:$F$89, 2, TRUE), IF(F6="PB", VLOOKUP(S21,String!$H$53:$I$93, 2, TRUE), IF(F6="BW", VLOOKUP(S21,String!$K$53:$L$85, 2, TRUE)))) -> PB024 | I21: 25.5 | J21: =VLOOKUP(G21, Pitch!$A$4:$B$52, 2, FALSE) -> 164.81378 | K21: =S21*(2*I21*J21)^2/386.4 -> 21.360306 | L21: =K20+K21 -> 42.062816 | M21: =SUM(SUM(M6-VLOOKUP(G21,Pitch!$F$58:$G$106,2,FALSE)))/SUM(VLOOKUP(VLOOKUP(MAX(J10:J21),Pitch!$A$58:$B$106,2,FALSE),Pitch!$F$58:$G$106,2,FALSE)-VLOOKUP(VLOOKUP(MIN(J10:J21),Pitch!$A$58:$B$106,2,FALSE),Pitch!$F$58:$G$106,2,FALSE))*M5 -> 0 | N21: =(K6/12)*(1+M21) -> 20.833333 | O21: =N21*386.4/(2*J21*I21)^2 -> 0.00011393797 | P21: =IF(F6="NW",IF(O21<String!$E$53,String!$E$53,IF(O21>String!$E$89,String!$E$89,O21)),IF(F6="BW",IF(O21<String!$K$53,String!$K$53,IF(O21>String!$K$85,String!$K$85,O21)),IF(O21<String!$H$53,String!$H$53,IF(O21>String!$H$93,String!$H$93,O21)))) -> 0.00011393797 | Q21: =IF(F6="NW",SMALL(String!$E$53:$E$89,COUNTIF(String!$E$53:$E$89,"<"&P21)+1),IF(F6="BW",SMALL(String!$K$53:$K$85,COUNTIF(String!$K$53:$K$85,"<"&P21)+1),SMALL(String!$H$53:$H$93,COUNTIF(String!$H$53:$H$93,"<"&P21)+1))) -> 0.00011682 | R21: =IF(F6="NW",LARGE(String!$E$53:$E$89,COUNTIF(String!$E$53:$E$89,">"&P21)+1),IF(F6="BW",LARGE(String!$K$53:$K$85,COUNTIF(String!$K$53:$K$85,">"&P21)+1),LARGE(String!$H$53:$H$93,COUNTIF(String!$H$53:$H$93,">"&P21)+1))) -> 0.00010801 | S21: =IF((P21-Q21)>(R21-P21),Q21,R21) -> 0.00011682
K23: =SUM(K10:K21) -> 252.25608 | L23: Total
K24: =K23/12 -> 21.02134 | L24: Average
K25: =MAX(K10:K21)-MIN(K10:K21) -> 1.2758356 | L25: Range | N25: =MAX(N10:N21)-MIN(N10:N21) -> 0 | O25: Target Range
E29: Manual Tension Calculator | N29: Reference Calculator for Pre-Packaged Sets
E30: String Family | N30: String Family | O30: String Set
F31: PB | N31: PB | O31: EJ38 10-47 Light
G32: Pitch | H32: String Model | I32: Scale (in) | J32: Frequency | K32: Tension | L32: Tension/Course | O32: Pitch | P32: String Model | Q32: Scale (in) | R32: Frequency | S32: Tension | T32: Tension/Course
F33: String 1 | G33: E4 | H33: PL0115 | I33: 25.5 | J33: =VLOOKUP(G33, Pitch!$A$4:$B$52, 2, FALSE) -> 329.62756 | K33: =VLOOKUP(H33,String!$A$8:$B$33, 2, FALSE)*(2*I33*J33)^2/386.4 -> 21.429788 | N33: String 1 | O33: E4 | P33: =IF(LEFT((O31),7)="EJ36 10",String!$L$117,IF(LEFT((O31),7)="EXL150 ",String!$P$134,IF(LEFT((O31),7)="EJ41 9-",String!$P$101,IF(LEFT((O31),7)="EJ38 10",String!$R$101,IF(LEFT((O31),7)="EJ39 12",String!$T$101,String!$V$101))))) -> PL010 | Q33: 25.5 | R33: =VLOOKUP(O33, Pitch!$A$4:$B$52, 2, FALSE) -> 329.62756 | S33: =IF(LEFT(P33,2)="PL",VLOOKUP(P33,String!$A$8:$B$33,2,FALSE),IF(LEFT(P33,2)="PB",VLOOKUP(P33,String!$G$8:$H$48,2,FALSE),IF(LEFT(P33,2)="BW",VLOOKUP(P33,String!$J$8:$K$40,2,FALSE),VLOOKUP(P33,String!$D$8:$E$44,2,FALSE))))*(2*Q33*R33)^2/386.4 -> 16.200335
F34: String 2 | G34: E4 | H34: PL0115 | I34: 25.5 | J34: =VLOOKUP(G34, Pitch!$A$4:$B$52, 2, FALSE) -> 329.62756 | K34: =VLOOKUP(H34,String!$A$8:$B$33, 2, FALSE)*(2*I34*J34)^2/386.4 -> 21.429788 | L34: =K33+K34 -> 42.859576 | N34: String 2 | O34: E4 | P34: =IF(LEFT((O31),7)="EJ36 10",String!$L$118,IF(LEFT((O31),7)="EXL150 ",String!$P$135,IF(LEFT((O31),7)="EJ41 9-",String!$P$102,IF(LEFT((O31),7)="EJ38 10",String!$R$102,IF(LEFT((O31),7)="EJ39 12",String!$T$102,String!$V$102))))) -> PL010 | Q34: 25.5 | R34: =VLOOKUP(O34, Pitch!$A$4:$B$52, 2, FALSE) -> 329.62756 | S34: =IF(LEFT(P34,2)="PL",VLOOKUP(P34,String!$A$8:$B$33,2,FALSE),IF(LEFT(P34,2)="PB",VLOOKUP(P34,String!$G$8:$H$48,2,FALSE),IF(LEFT(P34,2)="BW",VLOOKUP(P34,String!$J$8:$K$40,2,FALSE),VLOOKUP(P34,String!$D$8:$E$44,2,FALSE))))*(2*Q34*R34)^2/386.4 -> 16.200335 | T34: =S33+S34 -> 32.400669
F35: String 3 | G35: B3 | H35: PL015 | I35: 25.5 | J35: =VLOOKUP(G35, Pitch!$A$4:$B$52, 2, FALSE) -> 246.94165 | K35: =VLOOKUP(H35,String!$A$8:$B$33, 2, FALSE)*(2*I35*J35)^2/386.4 -> 20.45832 | N35: String 3 | O35: B3 | P35: =IF(LEFT((O31),7)="EJ36 10",String!$L$119,IF(LEFT((O31),7)="EXL150 ",String!$P$136,IF(LEFT((O31),7)="EJ41 9-",String!$P$103,IF(LEFT((O31),7)="EJ38 10",String!$R$103,IF(LEFT((O31),7)="EJ39 12",String!$T$103,String!$V$103))))) -> PL014 | Q35: 25.5 | R35: =VLOOKUP(O35, Pitch!$A$4:$B$52, 2, FALSE) -> 246.94165 | S35: =IF(LEFT(P35,2)="PL",VLOOKUP(P35,String!$A$8:$B$33,2,FALSE),IF(LEFT(P35,2)="PB",VLOOKUP(P35,String!$G$8:$H$48,2,FALSE),IF(LEFT(P35,2)="BW",VLOOKUP(P35,String!$J$8:$K$40,2,FALSE),VLOOKUP(P35,String!$D$8:$E$44,2,FALSE))))*(2*Q35*R35)^2/386.4 -> 17.823039
F36: String 4 | G36: B3 | H36: PL015 | I36: 25.5 | J36: =VLOOKUP(G36, Pitch!$A$4:$B$52, 2, FALSE) -> 246.94165 | K36: =VLOOKUP(H36,String!$A$8:$B$33, 2, FALSE)*(2*I36*J36)^2/386.4 -> 20.45832 | L36: =K35+K36 -> 40.916639 | N36: String 4 | O36: B3 | P36: =IF(LEFT((O31),7)="EJ36 10",String!$L$120,IF(LEFT((O31),7)="EXL150 ",String!$P$137,IF(LEFT((O31),7)="EJ41 9-",String!$P$104,IF(LEFT((O31),7)="EJ38 10",String!$R$104,IF(LEFT((O31),7)="EJ39 12",String!$T$104,String!$V$104))))) -> PL014 | Q36: 25.5 | R36: =VLOOKUP(O36, Pitch!$A$4:$B$52, 2, FALSE) -> 246.94165 | S36: =IF(LEFT(P36,2)="PL",VLOOKUP(P36,String!$A$8:$B$33,2,FALSE),IF(LEFT(P36,2)="PB",VLOOKUP(P36,String!$G$8:$H$48,2,FALSE),IF(LEFT(P36,2)="BW",VLOOKUP(P36,String!$J$8:$K$40,2,FALSE),VLOOKUP(P36,String!$D$8:$E$44,2,FALSE))))*(2*Q36*R36)^2/386.4 -> 17.823039 | T36: =S35+S36 -> 35.646077
E37: Wound | F37: String 5 | G37: G3 | H37: PB020 | I37: 25.5 | J37: =VLOOKUP(G37, Pitch!$A$4:$B$52, 2, FALSE) -> 195.99772 | K37: =IFERROR(IF(E37="Plain",VLOOKUP(H37,String!$A$8:$B$33,2,FALSE),IF(F31="PB",VLOOKUP(H37,String!$G$8:$H$48,2,FALSE),IF(F31="BW",VLOOKUP(H37,String!$J$8:$K$40,2,FALSE),VLOOKUP(H37,String!$D$8:$E$44,2,FALSE))))*(2*I37*J37)^2/386.4,"Select String") -> 20.960994 | N37: String 5 | O37: G3 | P37: =IF(LEFT((O31),7)="EJ36 10",String!$L$121,IF(LEFT((O31),7)="EXL150 ",String!$P$138,IF(LEFT((O31),7)="EJ41 9-",String!$P$105,IF(LEFT((O31),7)="EJ38 10",String!$R$105,IF(LEFT((O31),7)="EJ39 12",String!$T$105,String!$V$105))))) -> PB023 | Q37: 25.5 | R37: =VLOOKUP(O37, Pitch!$A$4:$B$52, 2, FALSE) -> 195.99772 | S37: =IF(LEFT(P37,2)="PL",VLOOKUP(P37,String!$A$8:$B$33,2,FALSE),IF(LEFT(P37,2)="PB",VLOOKUP(P37,String!$G$8:$H$48,2,FALSE),IF(LEFT(P37,2)="BW",VLOOKUP(P37,String!$J$8:$K$40,2,FALSE),VLOOKUP(P37,String!$D$8:$E$44,2,FALSE))))*(2*Q37*R37)^2/386.4 -> 27.92989
F38: String 6 | G38: G4 | H38: PL0095 | I38: 25.5 | J38: =VLOOKUP(G38, Pitch!$A$4:$B$52, 2, FALSE) -> 391.99544 | K38: =VLOOKUP(H38,String!$A$8:$B$33, 2, FALSE)*(2*I38*J38)^2/386.4 -> 20.676549 | L38: =IFERROR((K37+K38),"Select String") -> 41.637542 | N38: String 6 | O38: G4 | P38: =IF(LEFT((O31),7)="EJ36 10",String!$L$122,IF(LEFT((O31),7)="EXL150 ",String!$P$139,IF(LEFT((O31),7)="EJ41 9-",String!$P$106,IF(LEFT((O31),7)="EJ38 10",String!$R$106,IF(LEFT((O31),7)="EJ39 12",String!$T$106,String!$V$106))))) -> PL008 | Q38: 25.5 | R38: =VLOOKUP(O38, Pitch!$A$4:$B$52, 2, FALSE) -> 391.99544 | S38: =IF(LEFT(P38,2)="PL",VLOOKUP(P38,String!$A$8:$B$33,2,FALSE),IF(LEFT(P38,2)="PB",VLOOKUP(P38,String!$G$8:$H$48,2,FALSE),IF(LEFT(P38,2)="BW",VLOOKUP(P38,String!$J$8:$K$40,2,FALSE),VLOOKUP(P38,String!$D$8:$E$44,2,FALSE))))*(2*Q38*R38)^2/386.4 -> 14.667007 | T38: =S37+S38 -> 42.596897
F39: String 7 | G39: D3 | H39: PB027 | I39: 25.5 | J39: =VLOOKUP(G39, Pitch!$A$4:$B$52, 2, FALSE) -> 146.83238 | K39: =IFERROR(IF(F31="PB",VLOOKUP(H39,String!$G$8:$H$48,2,FALSE),IF(F31="BW",VLOOKUP(H39,String!$J$8:$K$40,2,FALSE),VLOOKUP(H39,String!$D$8:$E$44,2,FALSE)))*(2*I39*J39)^2/386.4,"Select String") -> 21.528076 | N39: String 7 | O39: D3 | P39: =IF(LEFT((O31),7)="EJ36 10",String!$L$123,IF(LEFT((O31),7)="EXL150 ",String!$P$140,IF(LEFT((O31),7)="EJ41 9-",String!$P$107,IF(LEFT((O31),7)="EJ38 10",String!$R$107,IF(LEFT((O31),7)="EJ39 12",String!$T$107,String!$V$107))))) -> PB030 | Q39: 25.5 | R39: =VLOOKUP(O39, Pitch!$A$4:$B$52, 2, FALSE) -> 146.83238 | S39: =IF(LEFT(P39,2)="PL",VLOOKUP(P39,String!$A$8:$B$33,2,FALSE),IF(LEFT(P39,2)="PB",VLOOKUP(P39,String!$G$8:$H$48,2,FALSE),IF(LEFT(P39,2)="BW",VLOOKUP(P39,String!$J$8:$K$40,2,FALSE),VLOOKUP(P39,String!$D$8:$E$44,2,FALSE))))*(2*Q39*R39)^2/386.4 -> 27.080618
F40: String 8 | G40: D4 | H40: PL013 | I40: 25.5 | J40: =VLOOKUP(G40, Pitch!$A$4:$B$52, 2, FALSE) -> 293.66477 | K40: =VLOOKUP(H40,String!$A$8:$B$33, 2, FALSE)*(2*I40*J40)^2/386.4 -> 21.734155 | L40: =IFERROR((K39+K40),"Select String") -> 43.262231 | N40: String 8 | O40: D4 | P40: =IF(LEFT((O31),7)="EJ36 10",String!$L$124,IF(LEFT((O31),7)="EXL150 ",String!$P$141,IF(LEFT((O31),7)="EJ41 9-",String!$P$108,IF(LEFT((O31),7)="EJ38 10",String!$R$108,IF(LEFT((O31),7)="EJ39 12",String!$T$108,String!$V$108))))) -> PL012 | Q40: 25.5 | R40: =VLOOKUP(O40, Pitch!$A$4:$B$52, 2, FALSE) -> 293.66477 | S40: =IF(LEFT(P40,2)="PL",VLOOKUP(P40,String!$A$8:$B$33,2,FALSE),IF(LEFT(P40,2)="PB",VLOOKUP(P40,String!$G$8:$H$48,2,FALSE),IF(LEFT(P40,2)="BW",VLOOKUP(P40,String!$J$8:$K$40,2,FALSE),VLOOKUP(P40,String!$D$8:$E$44,2,FALSE))))*(2*Q40*R40)^2/386.4 -> 18.51815 | T40: =S39+S40 -> 45.598769
F41: String 9 | G41: A2 | H41: PB035 | I41: 25.5 | J41: =VLOOKUP(G41, Pitch!$A$4:$B$52, 2, FALSE) -> 110 | K41: =IFERROR(IF(F31="PB",VLOOKUP(H41,String!$G$8:$H$48,2,FALSE),IF(F31="BW",VLOOKUP(H41,String!$J$8:$K$40,2,FALSE),VLOOKUP(H41,String!$D$8:$E$44,2,FALSE)))*(2*I41*J41)^2/386.4,"Select String") -> 20.659674 | N41: String 9 | O41: A2 | P41: =IF(LEFT((O31),7)="EJ36 10",String!$L$125,IF(LEFT((O31),7)="EXL150 ",String!$P$142,IF(LEFT((O31),7)="EJ41 9-",String!$P$109,IF(LEFT((O31),7)="EJ38 10",String!$R$109,IF(LEFT((O31),7)="EJ39 12",String!$T$109,String!$V$109))))) -> PB039 | Q41: 25.5 | R41: =VLOOKUP(O41, Pitch!$A$4:$B$52, 2, FALSE) -> 110 | S41: =IF(LEFT(P41,2)="PL",VLOOKUP(P41,String!$A$8:$B$33,2,FALSE),IF(LEFT(P41,2)="PB",VLOOKUP(P41,String!$G$8:$H$48,2,FALSE),IF(LEFT(P41,2)="BW",VLOOKUP(P41,String!$J$8:$K$40,2,FALSE),VLOOKUP(P41,String!$D$8:$E$44,2,FALSE))))*(2*Q41*R41)^2/386.4 -> 25.351168
E42: Plain | F42: String 10 | G42: A3 | H42: PL017 | I42: 25.5 | J42: =VLOOKUP(G42, Pitch!$A$4:$B$52, 2, FALSE) -> 220 | K42: =IFERROR(IF(E42="Plain",VLOOKUP(H42,String!$A$8:$B$33,2,FALSE),IF(F31="PB",VLOOKUP(H42,String!$G$8:$H$48,2,FALSE),IF(F31="BW",VLOOKUP(H42,String!$J$8:$K$40,2,FALSE),VLOOKUP(H42,String!$D$8:$E$44,2,FALSE))))*(2*I42*J42)^2/386.4,"Select String") -> 20.857597 | L42: =IFERROR((K41+K42),"Select String") -> 41.517271 | N42: String 10 | O42: A3 | P42: =IF(LEFT((O31),7)="EJ36 10",String!$L$126,IF(LEFT((O31),7)="EXL150 ",String!$P$143,IF(LEFT((O31),7)="EJ41 9-",String!$P$110,IF(LEFT((O31),7)="EJ38 10",String!$R$110,IF(LEFT((O31),7)="EJ39 12",String!$T$110,String!$V$110))))) -> PL018 | Q42: 25.5 | R42: =VLOOKUP(O42, Pitch!$A$4:$B$52, 2, FALSE) -> 220 | S42: =IF(LEFT(P42,2)="PL",VLOOKUP(P42,String!$A$8:$B$33,2,FALSE),IF(LEFT(P42,2)="PB",VLOOKUP(P42,String!$G$8:$H$48,2,FALSE),IF(LEFT(P42,2)="BW",VLOOKUP(P42,String!$J$8:$K$40,2,FALSE),VLOOKUP(P42,String!$D$8:$E$44,2,FALSE))))*(2*Q42*R42)^2/386.4 -> 23.187053 | T42: =S41+S42 -> 48.538221
F43: String 11 | G43: E2 | H43: PB047 | I43: 25.5 | J43: =VLOOKUP(G43, Pitch!$A$4:$B$52, 2, FALSE) -> 82.406889 | K43: =IFERROR(IF(F31="PB",VLOOKUP(H43,String!$G$8:$H$48,2,FALSE),IF(F31="BW",VLOOKUP(H43,String!$J$8:$K$40,2,FALSE),VLOOKUP(H43,String!$D$8:$E$44,2,FALSE)))*(2*I43*J43)^2/386.4,"Select String") -> 20.70251 | N43: String 11 | O43: E2 | P43: =IF(LEFT((O31),7)="EJ36 10",String!$L$127,IF(LEFT((O31),7)="EXL150 ",String!$P$144,IF(LEFT((O31),7)="EJ41 9-",String!$P$111,IF(LEFT((O31),7)="EJ38 10",String!$R$111,IF(LEFT((O31),7)="EJ39 12",String!$T$111,String!$V$111))))) -> PB047 | Q43: 25.5 | R43: =VLOOKUP(O43, Pitch!$A$4:$B$52, 2, FALSE) -> 82.406889 | S43: =IF(LEFT(P43,2)="PL",VLOOKUP(P43,String!$A$8:$B$33,2,FALSE),IF(LEFT(P43,2)="PB",VLOOKUP(P43,String!$G$8:$H$48,2,FALSE),IF(LEFT(P43,2)="BW",VLOOKUP(P43,String!$J$8:$K$40,2,FALSE),VLOOKUP(P43,String!$D$8:$E$44,2,FALSE))))*(2*Q43*R43)^2/386.4 -> 20.70251
F44: String 12 | G44: E3 | H44: PB024 | I44: 25.5 | J44: =VLOOKUP(G44, Pitch!$A$4:$B$52, 2, FALSE) -> 164.81378 | K44: =IFERROR(IF(F31="PB",VLOOKUP(H44,String!$G$8:$H$48,2,FALSE),IF(F31="BW",VLOOKUP(H44,String!$J$8:$K$40,2,FALSE),VLOOKUP(H44,String!$D$8:$E$44,2,FALSE)))*(2*I44*J44)^2/386.4,"Select String") -> 21.360306 | L44: =IFERROR((K43+K44),"Select String") -> 42.062816 | N44: String 12 | O44: E3 | P44: =IF(LEFT((O31),7)="EJ36 10",String!$L$128,IF(LEFT((O31),7)="EXL150 ",String!$P$145,IF(LEFT((O31),7)="EJ41 9-",String!$P$112,IF(LEFT((O31),7)="EJ38 10",String!$R$112,IF(LEFT((O31),7)="EJ39 12",String!$T$112,String!$V$112))))) -> PB027 | Q44: 25.5 | R44: =VLOOKUP(O44, Pitch!$A$4:$B$52, 2, FALSE) -> 164.81378 | S44: =IF(LEFT(P44,2)="PL",VLOOKUP(P44,String!$A$8:$B$33,2,FALSE),IF(LEFT(P44,2)="PB",VLOOKUP(P44,String!$G$8:$H$48,2,FALSE),IF(LEFT(P44,2)="BW",VLOOKUP(P44,String!$J$8:$K$40,2,FALSE),VLOOKUP(P44,String!$D$8:$E$44,2,FALSE))))*(2*Q44*R44)^2/386.4 -> 27.123676 | T44: =S43+S44 -> 47.826186
K46: =SUM(K33:K44) -> 252.25608 | L46: Total | S46: =SUM(S33:S44) -> 252.60682 | T46: Total
K47: =K46/12 -> 21.02134 | L47: Average | S47: =S46/12 -> 21.050568 | T47: Average
...

Sheet Scratch Paper

Sheet Pitch
A1: Pitch and Note Data
A2: Note to Frequency Values | L2: Note Number Reference
A3: Note | B3: Frequency | M3: Pitch | N3: Note # | O3: Frequency | P3: Pitch
A4: A4 | B4: =B5*2^(1/12) -> 440 | M4: C | N4: =ROUND(SUM(69+12*LOG(O4/440,2)),0) -> 0 | O4: =O5/2^(1/12) -> 8.1757989 | P4: C
A5: G#4 | B5: =B6*2^(1/12) -> 415.3047 | M5: C# | N5: =ROUND(SUM(69+12*LOG(O5/440,2)),0) -> 1 | O5: =O6/2^(1/12) -> 8.6619572 | P5: C#
A6: G4 | B6: =B7*2^(1/12) -> 391.99544 | M6: D | N6: =ROUND(SUM(69+12*LOG(O6/440,2)),0) -> 2 | O6: =O7/2^(1/12) -> 9.177024 | P6: D
A7: F#4 | B7: =B8*2^(1/12) -> 369.99442 | M7: D# | N7: =ROUND(SUM(69+12*LOG(O7/440,2)),0) -> 3 | O7: =O8/2^(1/12) -> 9.7227182 | P7: D#
A8: F4 | B8: =B9*2^(1/12) -> 349.22823 | M8: E | N8: =ROUND(SUM(69+12*LOG(O8/440,2)),0) -> 4 | O8: =O9/2^(1/12) -> 10.300861 | P8: E
A9: E4 | B9: =B10*2^(1/12) -> 329.62756 | M9: F | N9: =ROUND(SUM(69+12*LOG(O9/440,2)),0) -> 5 | O9: =O10/2^(1/12) -> 10.913382 | P9: F
A10: D#4 | B10: =B11*2^(1/12) -> 311.12698 | M10: F# | N10: =ROUND(SUM(69+12*LOG(O10/440,2)),0) -> 6 | O10: =O11/2^(1/12) -> 11.562326 | P10: F#
A11: D4 | B11: =B12*2^(1/12) -> 293.66477 | M11: G | N11: =ROUND(SUM(69+12*LOG(O11/440,2)),0) -> 7 | O11: =O12/2^(1/12) -> 12.249857 | P11: G
A12: C#4 | B12: =B13*2^(1/12) -> 277.18263 | M12: G# | N12: =ROUND(SUM(69+12*LOG(O12/440,2)),0) -> 8 | O12: =O13/2^(1/12) -> 12.978272 | P12: G#
A13: C4 | B13: =B14*2^(1/12) -> 261.62557 | C13: middle C | M13: A | N13: =ROUND(SUM(69+12*LOG(O13/440,2)),0) -> 9 | O13: =O14/2^(1/12) -> 13.75 | P13: A
A14: B3 | B14: =B15*2^(1/12) -> 246.94165 | M14: A# | N14: =ROUND(SUM(69+12*LOG(O14/440,2)),0) -> 10 | O14: =O15/2^(1/12) -> 14.567618 | P14: A#
A15: A#3 | B15: =B16*2^(1/12) -> 233.08188 | M15: B | N15: =ROUND(SUM(69+12*LOG(O15/440,2)),0) -> 11 | O15: =O16/2^(1/12) -> 15.433853 | P15: B
A16: A3 | B16: =B17*2^(1/12) -> 220 | M16: C0 | N16: =ROUND(SUM(69+12*LOG(O16/440,2)),0) -> 12 | O16: =O17/2^(1/12) -> 16.351598 | P16: C0
A17: G#3 | B17: =B18*2^(1/12) -> 207.65235 | M17: C#0 | N17: =ROUND(SUM(69+12*LOG(O17/440,2)),0) -> 13 | O17: =O18/2^(1/12) -> 17.323914 | P17: C#0
A18: G3 | B18: =B19*2^(1/12) -> 195.99772 | M18: D0 | N18: =ROUND(SUM(69+12*LOG(O18/440,2)),0) -> 14 | O18: =O19/2^(1/12) -> 18.354048 | P18: D0
A19: F#3 | B19: =B20*2^(1/12) -> 184.99721 | M19: D#0 | N19: =ROUND(SUM(69+12*LOG(O19/440,2)),0) -> 15 | O19: =O20/2^(1/12) -> 19.445436 | P19: D#0
A20: F3 | B20: =B21*2^(1/12) -> 174.61412 | M20: E0 | N20: =ROUND(SUM(69+12*LOG(O20/440,2)),0) -> 16 | O20: =O21/2^(1/12) -> 20.601722 | P20: E0
A21: E3 | B21: =B22*2^(1/12) -> 164.81378 | M21: F0 | N21: =ROUND(SUM(69+12*LOG(O21/440,2)),0) -> 17 | O21: =O22/2^(1/12) -> 21.826764 | P21: F0
A22: D#3 | B22: =B23*2^(1/12) -> 155.56349 | M22: F#0 | N22: =ROUND(SUM(69+12*LOG(O22/440,2)),0) -> 18 | O22: =O23/2^(1/12) -> 23.124651 | P22: F#0
A23: D3 | B23: =B24*2^(1/12) -> 146.83238 | M23: G0 | N23: =ROUND(SUM(69+12*LOG(O23/440,2)),0) -> 19 | O23: =O24/2^(1/12) -> 24.499715 | P23: G0
A24: C#3 | B24: =B25*2^(1/12) -> 138.59132 | M24: G#0 | N24: =ROUND(SUM(69+12*LOG(O24/440,2)),0) -> 20 | O24: =O25/2^(1/12) -> 25.956544 | P24: G#0
A25: C3 | B25: =B26*2^(1/12) -> 130.81278 | M25: A0 | N25: =ROUND(SUM(69+12*LOG(O25/440,2)),0) -> 21 | O25: =O26/2^(1/12) -> 27.5 | P25: A0
... A51: A#0 | B51: =B52*2^(1/12) -> 29.135235 | M51: B2 | N51: =ROUND(SUM(69+12*LOG(O51/440,2)),0) -> 47 | O51: =O52/2^(1/12) -> 123.47083 | P51: B2
A52: A0 | B52: 27.5 | M52: C3 | N52: =ROUND(SUM(69+12*LOG(O52/440,2)),0) -> 48 | O52: =O53/2^(1/12) -> 130.81278 | P52: C3
M53: C#3 | N53: =ROUND(SUM(69+12*LOG(O53/440,2)),0) -> 49 | O53: =O54/2^(1/12) -> 138.59132 | P53: C#3
M54: D3 | N54: =ROUND(SUM(69+12*LOG(O54/440,2)),0) -> 50 | O54: =O55/2^(1/12) -> 146.83238 | P54: D3
M55: D#3 | N55: =ROUND(SUM(69+12*LOG(O55/440,2)),0) -> 51 | O55: =O56/2^(1/12) -> 155.56349 | P55: D#3
M56: E3 | N56: =ROUND(SUM(69+12*LOG(O56/440,2)),0) -> 52 | O56: =O57/2^(1/12) -> 164.81378 | P56: E3
A57: Pitch | B57: Note | C57: Note # | F57: Note | G57: Note # | H57: Pitch | M57: F3 | N57: =ROUND(SUM(69+12*LOG(O57/440,2)),0) -> 53 | O57: =O58/2^(1/12) -> 174.61412 | P57: F3
A58: =A59*2^(1/12) -> 440 | B58: A4 | C58: =ROUND(SUM(69+12*LOG(A58/440,2)),0) -> 69 | F58: A0 | G58: =ROUND(SUM(69+12*LOG(H58/440,2)),0) -> 21 | H58: 27.5 | I58: A0 | M58: F#3 | N58: =ROUND(SUM(69+12*LOG(O58/440,2)),0) -> 54 | O58: =O59/2^(1/12) -> 184.99721 | P58: F#3
A59: =A60*2^(1/12) -> 415.3047 | B59: G#4 | C59: =ROUND(SUM(69+12*LOG(A59/440,2)),0) -> 68 | F59: A#0 | G59: =ROUND(SUM(69+12*LOG(H59/440,2)),0) -> 22 | H59: =H58*2^(1/12) -> 29.135235 | I59: A#0 | M59: G3 | N59: =ROUND(SUM(69+12*LOG(O59/440,2)),0) -> 55 | O59: =O60/2^(1/12) -> 195.99772 | P59: G3
A60: =A61*2^(1/12) -> 391.99544 | B60: G4 | C60: =ROUND(SUM(69+12*LOG(A60/440,2)),0) -> 67 | F60: B0 | G60: =ROUND(SUM(69+12*LOG(H60/440,2)),0) -> 23 | H60: =H59*2^(1/12) -> 30.867706 | I60: B0 | M60: G#3 | N60: =ROUND(SUM(69+12*LOG(O60/440,2)),0) -> 56 | O60: =O61/2^(1/12) -> 207.65235 | P60: G#3
A61: =A62*2^(1/12) -> 369.99442 | B61: F#4 | C61: =ROUND(SUM(69+12*LOG(A61/440,2)),0) -> 66 | F61: C1 | G61: =ROUND(SUM(69+12*LOG(H61/440,2)),0) -> 24 | H61: =H60*2^(1/12) -> 32.703196 | I61: C1 | M61: A3 | N61: =ROUND(SUM(69+12*LOG(O61/440,2)),0) -> 57 | O61: =O62/2^(1/12) -> 220 | P61: A3
A62: =A63*2^(1/12) -> 349.22823 | B62: F4 | C62: =ROUND(SUM(69+12*LOG(A62/440,2)),0) -> 65 | F62: C#1 | G62: =ROUND(SUM(69+12*LOG(H62/440,2)),0) -> 25 | H62: =H61*2^(1/12) -> 34.647829 | I62: C#1 | M62: A#3 | N62: =ROUND(SUM(69+12*LOG(O62/440,2)),0) -> 58 | O62: =O63/2^(1/12) -> 233.08188 | P62: A#3
A63: =A64*2^(1/12) -> 329.62756 | B63: E4 | C63: =ROUND(SUM(69+12*LOG(A63/440,2)),0) -> 64 | F63: D1 | G63: =ROUND(SUM(69+12*LOG(H63/440,2)),0) -> 26 | H63: =H62*2^(1/12) -> 36.708096 | I63: D1 | M63: B3 | N63: =ROUND(SUM(69+12*LOG(O63/440,2)),0) -> 59 | O63: =O64/2^(1/12) -> 246.94165 | P63: B3
A64: =A65*2^(1/12) -> 311.12698 | B64: D#4 | C64: =ROUND(SUM(69+12*LOG(A64/440,2)),0) -> 63 | F64: D#1 | G64: =ROUND(SUM(69+12*LOG(H64/440,2)),0) -> 27 | H64: =H63*2^(1/12) -> 38.890873 | I64: D#1 | L64: Middle C | M64: C4 | N64: =ROUND(SUM(69+12*LOG(O64/440,2)),0) -> 60 | O64: =O65/2^(1/12) -> 261.62557 | P64: C4 | Q64: Middle C
A65: =A66*2^(1/12) -> 293.66477 | B65: D4 | C65: =ROUND(SUM(69+12*LOG(A65/440,2)),0) -> 62 | F65: E1 | G65: =ROUND(SUM(69+12*LOG(H65/440,2)),0) -> 28 | H65: =H64*2^(1/12) -> 41.203445 | I65: E1 | M65: C#4 | N65: =ROUND(SUM(69+12*LOG(O65/440,2)),0) -> 61 | O65: =O66/2^(1/12) -> 277.18263 | P65: C#4
...

Sheet String
A1: String Model and Mass Data
A2: String Unit Weight (lb/in)
A3: Electric & Acoustic | D3: Electric | G3: Acoustic
A4: Plain | D4: Nickel-Wound | G4: Phoshpor Bronze | J4: 80/20s - Bronze
A5: PL-Series | D5: NW-Series | G5: PB-Series | J5: BW-Series
A6: PL String to Mass | D6: NW String to Mass | G6: PB String to Mass | J6: BW String to Mass
A7: String | B7: Unit Weight | D7: String | E7: Unit Weight | G7: String | H7: Unit Weight | J7: String | K7: Unit Weight
A8: PL007 | B8: 1.085e-05 | D8: NW017 | E8: 5.524e-05 | G8: PB016 | H8: =H21/4 -> 5.2545e-05 | J8: BW020 | K8: 7.862e-05
A9: PL008 | B9: 1.418e-05 | D9: NW018 | E9: 6.215e-05 | G9: PB017 | H9: =H22/4 -> 5.96925e-05 | J9: BW021 | K9: 8.684e-05
A10: PL0085 | B10: 1.601e-05 | D10: NW019 | E10: 6.947e-05 | G10: PB020 | H10: 8.106e-05 | J10: BW022 | K10: 9.6e-05
A11: PL009 | B11: 1.794e-05 | D11: NW020 | E11: 7.495e-05 | G11: PB021 | H11: 8.944e-05 | J11: BW023 | K11: 0.00010509
A12: PL0095 | B12: 1.999e-05 | D12: NW021 | E12: 8.293e-05 | G12: PB022 | H12: 9.876e-05 | J12: BW024 | K12: 0.00011353
A13: PL010 | B13: 2.215e-05 | D13: NW022 | E13: 9.184e-05 | G13: PB023 | H13: 0.00010801 | J13: BW025 | K13: 0.00012339
A14: PL0105 | B14: 2.442e-05 | D14: NW024 | E14: 0.00010857 | G14: PB024 | H14: 0.00011682 | J14: BW026 | K14: 0.00013253
A15: PL011 | B15: 2.68e-05 | D15: NW025 | E15: 0.00011254 | G15: PB025 | H15: 0.00012686 | J15: BW027 | K15: 0.00014397
A16: PL0115 | B16: 2.93e-05 | D16: NW026 | E16: 0.00012671 | G16: PB026 | H16: 0.0001364 | J16: BW029 | K16: 0.00016838
A17: PL012 | B17: 3.19e-05 | D17: NW028 | E17: 0.00014666 | G17: PB027 | H17: 0.00014834 | J17: BW030 | K17: 0.00018092
A18: PL0125 | B18: 3.41e-05 | D18: NW030 | E18: 0.00017236 | G18: PB028 | H18: =H39/4 -> 0.0001586925 | J18: BW031 | K18: 0.00019202
A19: PL013 | B19: 3.744e-05 | D19: NW032 | E19: 0.00019347 | G19: PB029 | H19: 0.00017381 | J19: BW032 | K19: 0.00020352
A20: PL0135 | B20: 4.037e-05 | D20: NW034 | E20: 0.0002159 | G20: PB030 | H20: 0.0001866 | J20: BW034 | K20: 0.00022752
A21: PL014 | B21: 4.342e-05 | D21: NW036 | E21: 0.00023964 | G21: PB032 | H21: 0.00021018 | J21: BW035 | K21: 0.00024006
A22: PL015 | B22: 4.984e-05 | D22: NW037 | E22: =E43/4 -> 0.0002471725 | G22: PB034 | H22: 0.00023877 | J22: BW036 | K22: 0.00025417
A23: PL0155 | B23: 5.2e-05 | D23: NW038 | E23: 0.00026471 | G23: PB035 | H23: 0.00025365 | J23: BW037 | K23: 0.00026927
A24: PL016 | B24: 5.671e-05 | D24: NW039 | E24: 0.00027932 | G24: PB036 | H24: 0.0002683 | J24: BW038 | K24: 0.00028757
A25: PL0165 | B25: 5.97e-05 | D25: NW040 | E25: =E11*4 -> 0.0002998 | G25: PB038 | H25: 0.0002933 | J25: BW039 | K25: 0.00030063
A26: PL017 | B26: 6.402e-05 | D26: NW042 | E26: 0.00032279 | G26: PB039 | H26: 0.00031125 | J26: BW040 | K26: =K8*4 -> 0.00031448
A27: PL018 | B27: 7.117e-05 | D27: NW044 | E27: 0.00035182 | G27: PB040 | H27: =H10*4 -> 0.00032424 | J27: BW042 | K27: 0.00034808
A28: PL019 | B28: 7.997e-05 | D28: NW046 | E28: 0.00038216 | G28: PB042 | H28: 0.00036722 | J28: BW044 | K28: =K10*4 -> 0.000384
A29: PL020 | B29: 8.861e-05 | D29: NW048 | E29: 0.00041382 | G29: PB044 | H29: =H12*4 -> 0.00039504 | J29: BW045 | K29: 0.00040245
A30: PL021 | B30: =B14*4 -> 9.768e-05 | D30: NW049 | E30: 0.00043014 | G30: PB045 | H30: 0.00041751 | J30: BW046 | K30: =K11*4 -> 0.00042036
A31: PL022 | B31: 0.00010722 | D31: NW050 | E31: =E15*4 -> 0.00045016 | G31: PB046 | H31: =H13*4 -> 0.00043204 | J31: BW047 | K31: 0.00043634
A32: PL024 | B32: 0.0001276 | D32: NW052 | E32: 0.00048109 | G32: PB047 | H32: 0.00045289 | J32: BW048 | K32: =K12*4 -> 0.00045412
A33: PL026 | B33: 0.00014975 | D33: NW054 | E33: 0.00053838 | G33: PB048 | H33: =H14*4 -> 0.00046728 | J33: BW049 | K33: 0.00047368
D34: NW056 | E34: 0.00057598 | G34: PB049 | H34: 0.00049151 | J34: BW050 | K34: =K13*4 -> 0.00049356
D35: NW059 | E35: 0.00064191 | G35: PB050 | H35: =H15*4 -> 0.00050744 | J35: BW052 | K35: 0.00053224
D36: NW060 | E36: 0.00066542 | G36: PB052 | H36: 0.00055223 | J36: BW053 | K36: 0.00054852
D37: NW062 | E37: 0.00070697 | G37: PB053 | H37: 0.00056962 | J37: BW055 | K37: 0.00059132
D38: NW064 | E38: 0.00074984 | G38: PB054 | H38: =H17*4 -> 0.00059336 | J38: BW056 | K38: 0.00061132
D39: NW066 | E39: 0.00079889 | G39: PB056 | H39: 0.00063477 | J39: BW059 | K39: 0.00068005
D40: NW068 | E40: 0.00084614 | G40: PB058 | H40: =H19*4 -> 0.00069524 | J40: BW060 | K40: =K17*4 -> 0.00072368
...
